<robot name="test_robot">
  <material name="red">
    <color rgba="1.0 0.0 0.0 1"/>
  </material>

  <link name="base_link"/>

  <joint name="body1_joint" type="fixed">
    <parent link="base_link"/>
    <child  link="body1_link"/>
  </joint>
  <link name="body1_link">
    <visual>
      <geometry>
        <box size="0.3 0.3 0.2"/>
      </geometry>
      <origin xyz="0 0 0" rpy="0 0 0"/>
      <material name="red"/>
      </visual>
  </link>

  <joint name="body2_joint" type="revolute">
    <parent link="base_link"/>
    <child  link="body2_link"/>
    <axis xyz = "0 0 1"/>
    <origin xyz="0.5 0 0" rpy="0 0 0"/>
    <limit lower="-1.5" upper="1.5" effort="0" velocity="0"/>
  </joint>
  <link name="body2_link">
    <visual>
      <geometry>
        <box size="0.3 0.3 0.2"/>
      </geometry>
      <origin xyz="0 0 0" rpy="0 0 0"/>
      <material name="red"/>
    </visual>
  </link>
</robot>